Workbook

Sheet HA integration codes
A1: 4133 | B1: status_9_errorCode | C1: uint16 | D1: 0
A2: 4167 | B2: status_9_controlFlags | C2: uint16 | D2: 50432
A3: 41a2 | B3: status_9_lastError_0 | C3: uint16 | D3: 0
A4: 41a3 | B4: status_9_extErrorCode | C4: uint16 | D4: 0
A5: 41a5 | B5: status_9_lastError_1 | C5: uint16 | D5: 0
A6: 41ab | B6: status_9_lastError_3 | C6: uint16 | D6: 0
A7: 41ac | B7: status_9_lastError_2 | C7: uint16 | D7: 0
A8: 41be | B8: status_9_lastError_4 | C8: uint16 | D8: 0
A9: 41d7 | B9: status_9_extPrevErrorCode | C9: uint16 | D9: 0
A10: 41e2 | B10: status_9_extError_status_2 | C10: uint16 | D10: 53080
A11: 41e5 | B11: status_9_extError_status_3 | C11: uint16 | D11: 10617
A12: 41eb | B12: status_9_extError_status_1 | C12: uint16 | D12: 23623
... A15: 41f7 | B15: status_9_extError_status_5 | C15: uint16 | D15: 8
A16: 4625 | B16: status_8_compressorLimit_max | C16: int16 | D16: unit.hertz | E16: 0.01 | F16: 0
A17: 4638 | B17: status_8_temperatureHysteresis_off | C17: int16 | D17: unit.degrees_celcius | E17: 0.01 | F17: 0
A18: 4641 | B18: status_8_temperatureSetpoint_Cooling | C18: int16 | D18: unit.degrees_celcius | E18: 0.01 | F18: 0
A19: 4645 | B19: status_8_fanLimit_max | C19: int16 | D19: unit.rounds_per_minute | E19: 0
A20: 4655 | B20: status_8_temperatureSetpoint_Heating | C20: int16 | D20: unit.degrees_celcius | E20: 0.01 | F20: 0
A21: 4656 | B21: status_8_temperatureHysteresis_on | C21: int16 | D21: unit.degrees_celcius | E21: 0.01 | F21: 0
A22: 468f | B22: status_8_fanLimit_min | C22: int16 | D22: unit.rounds_per_minute | E22: 0
A23: 46c0 | B23: status_8_temperatureSetpoint_DHW | C23: int16 | D23: unit.degrees_celcius | E23: 0.01 | F23: 0
A24: 46ce | B24: status_8_manualCompressorSpeed | C24: int16 | D24: unit.hertz | E24: 0.01 | F24: 0
A25: 46ef | B25: status_8_compressorLimit_min | C25: int16 | D25: unit.hertz | E25: 0.01 | F25: 0
A26: 46f6 | B26: status_8_powerOn | C26: uint8 | D26: 1
A27: 473d | B27: CPUinfo_checksum | C27: bytes | D27: P
A28: 47b0 | B28: CPUinfo_date_code | C28: bytes | D28: P240516*
A29: 47b1 | B29: CPUinfo_crc | C29: bytes | D29: o | E29: t
A30: 47da | B30: CPUinfo_software_name | C30: bytes | D30: hbcumk1 | E30: *
A31: 47e0 | B31: CPUinfo_software_version | C31: bytes | D31: V0.60-
A32: 5008 | B32: status_S_energyThermalCoolingPrevDay | C32: int16 | D32: unit.kWh | E32: 0.1 | F32: 0
A33: 5031 | B33: status_S_copDhwPrevDay | C33: uint8 | D33: 0.1 | E33: 0
A34: 503e | B34: status_S_currentHpPowerThermal | C34: int16 | D34: unit.kilowatt | E34: 0.001 | F34: 0
A35: 503f | B35: status_S_energyElectricCoolingPrevDay | C35: int16 | D35: unit.kWh | E35: 0.1 | F35: 0
A36: 5041 | B36: status_S_currentCop | C36: uint8 | D36: 0.1 | E36: 0
A37: 5051 | B37: status_S_copCoolingPrevDay | C37: uint8 | D37: 0.1 | E37: 0
A38: 506a | B38: status_S_energyThermalBoilerPrevDay | C38: int16 | D38: unit.kWh | E38: 0.1 | F38: 0
A39: 5077 | B39: status_S_currentPowerThermal | C39: int16 | D39: unit.kilowatt | E39: 0.001 | F39: 0
A40: 5088 | B40: status_S_currentBoilerPowerThermal | C40: int16 | D40: unit.kilowatt | E40: 0.001 | F40: 0
A41: 5092 | B41: status_S_currentDhwPowerThermal | C41: int16 | D41: unit.kilowatt | E41: 0.001 | F41: 0
A42: 5098 | B42: status_S_energyThermalDhwPrevDay | C42: int16 | D42: unit.kWh | E42: 0.1 | F42: 0
...

Sheet XTEND screens
A1: codes requested by Xtend screen | C1: x means retrieved value is not shown on the XTEND screen | D1: #N/A means not available, not found
A3: XTEND HTTP-GET | B3: Example value | C3: Name shown on XTEND screen | D3: description from HA integration | E3: Domoticz plugin device name | F3: comments
A4: 2963 | B4: 0 | C4: x | D4: =VLOOKUP(A4,'HA integration codes'!$A$1:$B$282,2,FALSE) -> #N/A | E4: =VLOOKUP(A4,'PLUGIN devices'!$A$2:$B$54,2,FALSE) -> #N/A
A5: 4133 | B5: 0 | C5: x | D5: =VLOOKUP(A5,'HA integration codes'!$A$1:$B$282,2,FALSE) -> status_9_errorCode | E5: =VLOOKUP(A5,'PLUGIN devices'!$A$2:$B$54,2,FALSE) -> #N/A
A6: 47e0 | B6: V0.86- | C6: Firmware version | D6: =VLOOKUP(A6,'HA integration codes'!$A$1:$B$282,2,FALSE) -> CPUinfo_software_version | E6: =VLOOKUP(A6,'PLUGIN devices'!$A$2:$B$54,2,FALSE) -> Software version
A7: 4a22 | B7: 193 | C7: Heat Pump, Domestic hot water pump starts | D7: =VLOOKUP(A7,'HA integration codes'!$A$1:$B$282,2,FALSE) -> #N/A | E7: =VLOOKUP(A7,'PLUGIN devices'!$A$2:$B$54,2,FALSE) -> #N/A | F7: not DHW but HP pump starts ?
A8: 4a3c | B8: 253 | C8: Heat Pump, Crank heater starts | D8: =VLOOKUP(A8,'HA integration codes'!$A$1:$B$282,2,FALSE) -> #N/A | E8: =VLOOKUP(A8,'PLUGIN devices'!$A$2:$B$54,2,FALSE) -> #N/A
A9: 4a76 | B9: 0 | C9: x | D9: =VLOOKUP(A9,'HA integration codes'!$A$1:$B$282,2,FALSE) -> #N/A | E9: =VLOOKUP(A9,'PLUGIN devices'!$A$2:$B$54,2,FALSE) -> #N/A | F9: base pan heater starts or hours ?
A10: 4aeb | B10: 0 | C10: x | D10: =VLOOKUP(A10,'HA integration codes'!$A$1:$B$282,2,FALSE) -> #N/A | E10: =VLOOKUP(A10,'PLUGIN devices'!$A$2:$B$54,2,FALSE) -> #N/A | F10: base pan heater starts or hours ?
A11: 4e13 | B11: 251 | C11: Heat Pump, Domestic hot water pump hours | D11: =VLOOKUP(A11,'HA integration codes'!$A$1:$B$282,2,FALSE) -> #N/A | E11: =VLOOKUP(A11,'PLUGIN devices'!$A$2:$B$54,2,FALSE) -> #N/A | F11: not DHW but HP pump hours ?
A12: 4e3a | B12: 0 | C12: x | D12: =VLOOKUP(A12,'HA integration codes'!$A$1:$B$282,2,FALSE) -> #N/A | E12: =VLOOKUP(A12,'PLUGIN devices'!$A$2:$B$54,2,FALSE) -> #N/A | F12: base pan heater starts or hours ?
A13: 4eeb | B13: 24 | C13: Heat Pump, Crank heater hours | D13: =VLOOKUP(A13,'HA integration codes'!$A$1:$B$282,2,FALSE) -> #N/A | E13: =VLOOKUP(A13,'PLUGIN devices'!$A$2:$B$54,2,FALSE) -> #N/A
A14: 5008 | B14: 0 | C14: x | D14: =VLOOKUP(A14,'HA integration codes'!$A$1:$B$282,2,FALSE) -> status_S_energyThermalCoolingPrevDay | E14: =VLOOKUP(A14,'PLUGIN devices'!$A$2:$B$54,2,FALSE) -> #N/A
A15: 5031 | B15: 0 | C15: x | D15: =VLOOKUP(A15,'HA integration codes'!$A$1:$B$282,2,FALSE) -> status_S_copDhwPrevDay | E15: =VLOOKUP(A15,'PLUGIN devices'!$A$2:$B$54,2,FALSE) -> #N/A
A16: 503e | B16: 3414 | C16: Power, Heat pump | D16: =VLOOKUP(A16,'HA integration codes'!$A$1:$B$282,2,FALSE) -> status_S_currentHpPowerThermal | E16: =VLOOKUP(A16,'PLUGIN devices'!$A$2:$B$54,2,FALSE) -> HP energy generated
A17: 503f | B17: 0 | C17: x | D17: =VLOOKUP(A17,'HA integration codes'!$A$1:$B$282,2,FALSE) -> status_S_energyElectricCoolingPrevDay | E17: =VLOOKUP(A17,'PLUGIN devices'!$A$2:$B$54,2,FALSE) -> #N/A
A18: 5041 | B18: 43 | C18: Power, COP | D18: =VLOOKUP(A18,'HA integration codes'!$A$1:$B$282,2,FALSE) -> status_S_currentCop | E18: =VLOOKUP(A18,'PLUGIN devices'!$A$2:$B$54,2,FALSE) -> COP
A19: 5051 | B19: 0 | C19: x | D19: =VLOOKUP(A19,'HA integration codes'!$A$1:$B$282,2,FALSE) -> status_S_copCoolingPrevDay | E19: =VLOOKUP(A19,'PLUGIN devices'!$A$2:$B$54,2,FALSE) -> #N/A
A20: 506a | B20: 20 | C20: Energy, Boiler Generated, Previous Day | D20: =VLOOKUP(A20,'HA integration codes'!$A$1:$B$282,2,FALSE) -> status_S_energyThermalBoilerPrevDay | E20: =VLOOKUP(A20,'PLUGIN devices'!$A$2:$B$54,2,FALSE) -> #N/A
A21: 5077 | B21: 3414 | C21: Power, Total Thermal | D21: =VLOOKUP(A21,'HA integration codes'!$A$1:$B$282,2,FALSE) -> status_S_currentPowerThermal | E21: =VLOOKUP(A21,'PLUGIN devices'!$A$2:$B$54,2,FALSE) -> #N/A
A22: 5088 | B22: 0 | C22: Power, Boiler | D22: =VLOOKUP(A22,'HA integration codes'!$A$1:$B$282,2,FALSE) -> status_S_currentBoilerPowerThermal | E22: =VLOOKUP(A22,'PLUGIN devices'!$A$2:$B$54,2,FALSE) -> Bolier enery generated
A23: 5098 | B23: 0 | C23: x | D23: =VLOOKUP(A23,'HA integration codes'!$A$1:$B$282,2,FALSE) -> status_S_energyThermalDhwPrevDay | E23: =VLOOKUP(A23,'PLUGIN devices'!$A$2:$B$54,2,FALSE) -> #N/A
A24: 5099 | B24: 118 | C24: Energy, Heat Pump Used, Previous Day | D24: =VLOOKUP(A24,'HA integration codes'!$A$1:$B$282,2,FALSE) -> status_S_energyElectricHeatingPrevDay | E24: =VLOOKUP(A24,'PLUGIN devices'!$A$2:$B$54,2,FALSE) -> #N/A
... A56: 65c1 | B56: 600 | C56: Heat Pump, Refrigeration, Evaporator Temperature | D56: =VLOOKUP(A56,'HA integration codes'!$A$1:$B$282,2,FALSE) -> status_5_coilTemperature | E56: =VLOOKUP(A56,'PLUGIN devices'!$A$2:$B$54,2,FALSE) -> Coil temp
A57: 65d0 | B57: 11 | C57: Heat Pump, 4-way Valve Position | D57: =VLOOKUP(A57,'HA integration codes'!$A$1:$B$282,2,FALSE) -> status_5_digitalOut | E57: =VLOOKUP(A57,'PLUGIN devices'!$A$2:$B$54,2,FALSE) -> #N/A | F57: bit 3 of 16 indicates 4-way valve (ref HA integration)
A58: 65d9 | B58: 8700 | C58: Heat Pump, Refrigeration, Exhaust gas temperature | D58: =VLOOKUP(A58,'HA integration codes'!$A$1:$B$282,2,FALSE) -> status_5_exhaustTemperature | E58: =VLOOKUP(A58,'PLUGIN devices'!$A$2:$B$54,2,FALSE) -> Exhaust gas temp
A59: 6a28 | B59: 0 | C59: x | D59: =VLOOKUP(A59,'HA integration codes'!$A$1:$B$282,2,FALSE) -> statistics_5_startCoolingCounter | E59: =VLOOKUP(A59,'PLUGIN devices'!$A$2:$B$54,2,FALSE) -> #N/A
A60: 6a53 | B60: 3 | C60: Heat Pump, Defrost Cycles | D60: =VLOOKUP(A60,'HA integration codes'!$A$1:$B$282,2,FALSE) -> statistics_5_startDefrostCounter | E60: =VLOOKUP(A60,'PLUGIN devices'!$A$2:$B$54,2,FALSE) -> HP defrost cycles
A61: 6a6c | B61: 0 | C61: x | D61: =VLOOKUP(A61,'HA integration codes'!$A$1:$B$282,2,FALSE) -> statistics_5_operationDhwHours | E61: =VLOOKUP(A61,'PLUGIN devices'!$A$2:$B$54,2,FALSE) -> #N/A
A62: 6a78 | B62: 0 | C62: x | D62: =VLOOKUP(A62,'HA integration codes'!$A$1:$B$282,2,FALSE) -> statistics_5_operationCoolingHours | E62: =VLOOKUP(A62,'PLUGIN devices'!$A$2:$B$54,2,FALSE) -> #N/A
A63: 6a8d | B63: 0 | C63: x | D63: =VLOOKUP(A63,'HA integration codes'!$A$1:$B$282,2,FALSE) -> statistics_5_startDhwCounter | E63: =VLOOKUP(A63,'PLUGIN devices'!$A$2:$B$54,2,FALSE) -> Boiler DHW starts
A64: 6a8e | B64: 122 | C64: Heat Pump, Compressor Starts | D64: =VLOOKUP(A64,'HA integration codes'!$A$1:$B$282,2,FALSE) -> statistics_5_startHeatingCounter | E64: =VLOOKUP(A64,'PLUGIN devices'!$A$2:$B$54,2,FALSE) -> HP Compressor starts
A65: 6ac5 | B65: 177 | C65: Heat Pump, Runtime | D65: =VLOOKUP(A65,'HA integration codes'!$A$1:$B$282,2,FALSE) -> statistics_5_operationHeatingHours | E65: =VLOOKUP(A65,'PLUGIN devices'!$A$2:$B$54,2,FALSE) -> HP runtime
A66: 6c26 | B66: 6650 | C66: Heat Pump, Refrigeration, T condensor gas | D66: =VLOOKUP(A66,'HA integration codes'!$A$1:$B$282,2,FALSE) -> status_6_temperatureCondensor_refrigrerant_gas | E66: =VLOOKUP(A66,'PLUGIN devices'!$A$2:$B$54,2,FALSE) -> Condensor gas temp
A67: 6c33 | B67: 4434 | C67: Heat Pump, Refrigeration, Discharge overheat | D67: =VLOOKUP(A67,'HA integration codes'!$A$1:$B$282,2,FALSE) -> status_6_exhaustOverheat | E67: =VLOOKUP(A67,'PLUGIN devices'!$A$2:$B$54,2,FALSE) -> Discharge overheat temp
A68: 6c53 | B68: 202 | C68: Heat Pump, Refrigeration, subcooling | D68: =VLOOKUP(A68,'HA integration codes'!$A$1:$B$282,2,FALSE) -> status_6_temperatureSubcooling | E68: =VLOOKUP(A68,'PLUGIN devices'!$A$2:$B$54,2,FALSE) -> Subcooling temp
A69: 6c61 | B69: 410 | C69: x | D69: =VLOOKUP(A69,'HA integration codes'!$A$1:$B$282,2,FALSE) -> status_6_fanspeedSetpoint | E69: =VLOOKUP(A69,'PLUGIN devices'!$A$2:$B$54,2,FALSE) -> #N/A
... A77: 7774 | B77: 255 | C77: x | D77: =VLOOKUP(A77,'HA integration codes'!$A$1:$B$282,2,FALSE) -> #N/A | E77: =VLOOKUP(A77,'PLUGIN devices'!$A$2:$B$54,2,FALSE) -> #N/A
A78: 77c3 | B78: 131 | C78: Status, Silent Mode | D78: =VLOOKUP(A78,'HA integration codes'!$A$1:$B$282,2,FALSE) -> status_3_Flags | E78: =VLOOKUP(A78,'PLUGIN devices'!$A$2:$B$54,2,FALSE) -> #N/A | F78: bit 4 of 8 indicates silent mode (ref HA integration)
A79: 77d2 | B79: 18158 | C79: Operating Mode ? | D79: =VLOOKUP(A79,'HA integration codes'!$A$1:$B$282,2,FALSE) -> status_3_SystemIo | E79: =VLOOKUP(A79,'PLUGIN devices'!$A$2:$B$54,2,FALSE) -> #N/A
...

Sheet PLUGIN devices
A1: plugin code | B1: plugin text | C1: used on Xtend screens | D1: comment
A2: 47e0 | B2: Software version | C2: =VLOOKUP(A2,'XTEND screens'!$A$4:$C$106,3,FALSE) -> Firmware version
A3: 5041 | B3: COP | C3: =VLOOKUP(A3,'XTEND screens'!$A$4:$C$106,3,FALSE) -> Power, COP
A4: 503e | B4: HP energy generated | C4: =VLOOKUP(A4,'XTEND screens'!$A$4:$C$106,3,FALSE) -> Power, Heat pump | D4: was 5077 before, should be 503e for HP,5088 for Boiler, 5077 for total
A5: 5088 | B5: Bolier enery generated | C5: =VLOOKUP(A5,'XTEND screens'!$A$4:$C$106,3,FALSE) -> Power, Boiler
A6: 50f2 | B6: HP energy usage | C6: =VLOOKUP(A6,'XTEND screens'!$A$4:$C$106,3,FALSE) -> Power, Retrieved
A7: 7e81 | B7: Boiler CH return temp | C7: =VLOOKUP(A7,'XTEND screens'!$A$4:$C$106,3,FALSE) -> Boiler, CH Water, Return | D7: was 623c, 7e81 used on Xtend screen instead (but 32767 value)
A8: 625b | B8: Boiler CH supply temp | C8: =VLOOKUP(A8,'XTEND screens'!$A$4:$C$106,3,FALSE) -> #N/A | D8: 7ee6 used on Xtend screen, but already used for Boiler temp in plugin
A9: 6280 | B9: HP return temp | C9: =VLOOKUP(A9,'XTEND screens'!$A$4:$C$106,3,FALSE) -> Heat Pump, CH water, Return
A10: 629c | B10: HP CH flow | C10: =VLOOKUP(A10,'XTEND screens'!$A$4:$C$106,3,FALSE) -> Heat Pump, CH water, Flow
A11: 62cb | B11: Pump level | C11: =VLOOKUP(A11,'XTEND screens'!$A$4:$C$106,3,FALSE) -> #N/A | D11: not queried or used on Xtend screen
A12: 62e7 | B12: HP supply temp | C12: =VLOOKUP(A12,'XTEND screens'!$A$4:$C$106,3,FALSE) -> Heat Pump, CH water, Supply
A13: 62ed | B13: HP setpoint temp | C13: =VLOOKUP(A13,'XTEND screens'!$A$4:$C$106,3,FALSE) -> CH water, Setpoint
A14: 6505 | B14: Suction line gas temp | C14: =VLOOKUP(A14,'XTEND screens'!$A$4:$C$106,3,FALSE) -> Heat Pump, Refrigeration, Suction line gas temperature
A15: 62d1 | B15: Outside temp | C15: =VLOOKUP(A15,'XTEND screens'!$A$4:$C$106,3,FALSE) -> Temperatures, Outside | D15: was 6573 before, 62d1 used on Xtend screen instead
A16: 6578 | B16: Operating Mode | C16: =VLOOKUP(A16,'XTEND screens'!$A$4:$C$106,3,FALSE) -> Status, Operating Mode | D16: used for Operational Mode on Xtend screen ?
A17: 6579 | B17: HP suction pressure | C17: =VLOOKUP(A17,'XTEND screens'!$A$4:$C$106,3,FALSE) -> Heat Pump, Refrigeration, Suction gas pressure
A18: 657e | B18: Operation mode | C18: =VLOOKUP(A18,'XTEND screens'!$A$4:$C$106,3,FALSE) -> #N/A | D18: not queried or used on Xtend screen
A19: 65a7 | B19: Compressor frequency | C19: =VLOOKUP(A19,'XTEND screens'!$A$4:$C$106,3,FALSE) -> Heat Pump, Compressor Frequency
A20: 65b0 | B20: HP discharge gas pressure | C20: =VLOOKUP(A20,'XTEND screens'!$A$4:$C$106,3,FALSE) -> Heat Pump, Refrigeration, Discharge gas pressure
A21: 65c1 | B21: Coil temp | C21: =VLOOKUP(A21,'XTEND screens'!$A$4:$C$106,3,FALSE) -> Heat Pump, Refrigeration, Evaporator Temperature
A22: 65d9 | B22: Exhaust gas temp | C22: =VLOOKUP(A22,'XTEND screens'!$A$4:$C$106,3,FALSE) -> Heat Pump, Refrigeration, Exhaust gas temperature
A23: 6a53 | B23: HP defrost cycles | C23: =VLOOKUP(A23,'XTEND screens'!$A$4:$C$106,3,FALSE) -> Heat Pump, Defrost Cycles
A24: 6a8d | B24: Boiler DHW starts | C24: =VLOOKUP(A24,'XTEND screens'!$A$4:$C$106,3,FALSE) -> x | D24: queried but not shown on Xtend screen, disabled in my Domoticz
A25: 6a8e | B25: HP Compressor starts | C25: =VLOOKUP(A25,'XTEND screens'!$A$4:$C$106,3,FALSE) -> Heat Pump, Compressor Starts
A26: 6ac5 | B26: HP runtime | C26: =VLOOKUP(A26,'XTEND screens'!$A$4:$C$106,3,FALSE) -> Heat Pump, Runtime
A27: 6c26 | B27: Condensor gas temp | C27: =VLOOKUP(A27,'XTEND screens'!$A$4:$C$106,3,FALSE) -> Heat Pump, Refrigeration, T condensor gas
A28: 6c33 | B28: Discharge overheat temp | C28: =VLOOKUP(A28,'XTEND screens'!$A$4:$C$106,3,FALSE) -> Heat Pump, Refrigeration, Discharge overheat
A29: 6c53 | B29: Subcooling temp | C29: =VLOOKUP(A29,'XTEND screens'!$A$4:$C$106,3,FALSE) -> Heat Pump, Refrigeration, subcooling
A30: 6c8a | B30: Fan speed | C30: =VLOOKUP(A30,'XTEND screens'!$A$4:$C$106,3,FALSE) -> Heat pump, Fan Speed
A31: 6ceb | B31: Condensor liquid temp | C31: =VLOOKUP(A31,'XTEND screens'!$A$4:$C$106,3,FALSE) -> Heat Pump, Refrigeration, T condensor liquid
A32: 6cfb | B32: Suction line overheat temp | C32: =VLOOKUP(A32,'XTEND screens'!$A$4:$C$106,3,FALSE) -> Heat Pump, Refrigeration, Suction line overheat
A33: 712c | B33: Boiler ignition fail count | C33: =VLOOKUP(A33,'XTEND screens'!$A$4:$C$106,3,FALSE) -> #N/A | D33: not queried or used on Xtend screen
A34: 7160 | B34: HP power cycles | C34: =VLOOKUP(A34,'XTEND screens'!$A$4:$C$106,3,FALSE) -> Heat Pump, Power Cycles
A35: 71a7 | B35: HP poweron | C35: =VLOOKUP(A35,'XTEND screens'!$A$4:$C$106,3,FALSE) -> Heat Pump, Hours on Power
A36: 777d | B36: Heat demand HP | C36: =VLOOKUP(A36,'XTEND screens'!$A$4:$C$106,3,FALSE) -> #N/A | D36: not queried or used on Xtend screen, used instead of f9f2 bit 8
A37: 77dd | B37: System status | C37: =VLOOKUP(A37,'XTEND screens'!$A$4:$C$106,3,FALSE) -> #N/A | D37: not queried or used on Xtend screen
A38: 7921 | B38: Target room temp | C38: =VLOOKUP(A38,'XTEND screens'!$A$4:$C$106,3,FALSE) -> Temperatures, Target/Setpoint
A39: 79b3 | B39: Room temp | C39: =VLOOKUP(A39,'XTEND screens'!$A$4:$C$106,3,FALSE) -> Temperatures, Room
A40: 7e51 | B40: Device Status | C40: =VLOOKUP(A40,'XTEND screens'!$A$4:$C$106,3,FALSE) -> Heat Pump, Device Status | D40: renamed
...
